Workbook

Sheet Log
A1: Datum | B1: Beschrijving | C1: Wie
A2: 44434 | B2: Alle artikelgroepen met basis aangepast om het pakket Overall basis op te nemen ipv pakket nutriënten en pakket veldmetingen | C2: JvT
A3: 44466 | B3: Hybi frequenties op maanden gezet. Opletten dat de periode correct wordt gehanteerd. | C3: JvT
A4: 44798 | B4: pcd_ow geupdate | C4: JvT
A5: 44796 | B5: lablijst Dawaco toegevoegd. | C5: JvT
A6: 44798 | B6: tabblad artikelen-componenten moet worden vervangen door pdc_ow | C6: JvT
A7: 44799 | B7: De tabbladen met meetnetcodes, artikelgroepcodes en frequentiecodes gebruiken om velden op de andere bladen automatisch te vullen. De tabbladen meetnetten, artikelgroepen, artikelen en frequenties zijn voldoende om de meetvraag op te stellen. Het tabblad pdc_ow is nodig voor een controle met Dawaco en controle op dubbellingen. | C7: JvT
A8: 44799 | B8: artikelen aangepast en toegevoegd obv van nieuwe pdc en gewijzigde testen | C8: JvT
A9: 44799 | B9: pakket cfcz vervangen voor pakket negatief | C9: JvT
A10: 44809 | B10: feofytine-a en gloeirest zijn verwijderd uit alle artikelgroepen met zwevende bestanddelen | C10: JvT
A11: 44813 | B11: fosfor totaal na filtratie verwijderd uit artikelgroep defos ivm sterke overlap met ortho-fosfaat | C11: JvT
A12: 44813 | B12: Samenstelling GBM C en D zijn veranderd in 2023 | C12: JvT
A13: 44813 | B13: Locatiebezoek met boot verwijderd uit artikelgroep basis_diep. Locatiebezoek is niet nodig als ook aan de oppervlakte wordt gemeten | C13: JvT
... A23: 46044 | B23: CZV vervangen door TOC (pakket defos) | C23: JvT

Sheet Stappen
B1: Stappen die nodig zijn om een meetvraag te formuleren
A3: Stap | B3: Actie
A4: 0 | B4: Controle of alle koppelingen kloppen en aanwezig zijn (artikelgroepen, frequentiecodes etc.)
A5: 1 | B5: Wegfilteren van lege regels uit de verschillende tabellen
A6: 2 | B6: Wegfilteren van regels die niet meer actief zijn (datum_eind) uit meetnetten.
A7: 3 | B7: Selecteren van de juiste regels roulerende meetnetten obv meetjaarcode (NB meetjaarcode is het resultaat van REST([meetjaar];3)
A8: 4 | B8: Koppelen van artikelgroepen, artikelen en frequenties aan de meetnetten dmv left join. (Dit leidt tot ca. 24000 regels)
A9: 5

Sheet meetnetcodes
A1: meetnet_code | B1: meetnet_nr | C1: meetnet_omschrijving | D1: Afgesloten | E1: 2026 | F1: 2025 | G1: 2024 | H1: 2023 | I1: 2022 | J1: Beschrijving aanwezig | K1: VP (dd 27-9-2024)
A2: basis | B2: 1 | C2: Basis meetnet | J2: Ja | K2: 74820
A3: roulerend | B3: 2 | C3: Roulerend meetnet | J3: Ja | K3: 76259
A4: zwemwater | B4: 3 | C4: Zwemwatermeetnet | E4: Checken wat de laatste meetmomenten zijn voor Esch en ZWPlasje | J4: Ja | K4: 17752
A5: krw_chemie | B5: 4 | C5: KRW chemie | E5: Input Anne | F5: Checken met Anne voor eventuele aanpassingen | K5: 1046
A6: gbm | B6: 5 | C6: Bestrijdingsmiddelenmeetnet | E6: Vervangende locatie voor S_0609 | H6: Externe GBM glaspakket later toevoegen | K6: 40000
A7: basis_bio | B7: 6 | C7: Basismetingen biologie | K7: 14469
A8: waterparel | B8: 7 | C8: Meetnet waterparels | I8: dubbelling door verschillende Aquonpakketten (nutriënten en macro-ionen) - opgelost in code | K8: 5551
A9: krw_oc | B9: 8 | C9: KRW ondersteunende chemie | H9: alleen K_0108 | I9: alleen K_0110 | K9: 1169
A10: mnlso | B10: 90 | C10: Meetnet Nutriënten Landbouw Specifiek Oppervlaktewater | E10: Afwachten loc K_1408 | K10: 5845
A11: lmgbm | B11: 91 | C11: Landelijk Meetnet GewasBeschermingsMiddelen | E11: Vervangende locatie voor S_0609 | H11: Externe GBM glaspakket later toevoegen
A12: radio | B12: 92 | C12: Landelijk meetnet voor radioactiviteit | E12: NVT | F12: NVT | H12: weggefilterd in code | I12: weggefilterd in code
A13: krw_bio | B13: 101 | C13: KRW biologie | E13: Anne | K13: 29321
A14: quickscan | B14: 102 | C14: Quickscan vegetatie | E14: Anne | K14: 22562
A15: vegvlk | B15: 103 | C15: Vlakdekkende vegetatieopnamen | E15: Anne | K15: 21090
A16: kreeften | B16: 104 | C16: Kreeftenmonitoring | E16: niet bij Aquon | F16: niet bij Aquon | I16: Check Anne?
A17: vis_overig | B17: 105 | C17: Visstandsonderzoek buiten KRW | E17: niet bij Aquon | F17: niet bij Aquon
A18: ijking_egv | B18: 1003 | C18: IJking continumeters EGV | D18: TRUE | I18: Niet voortzetten. Onderhoud en ijking meters dient op een betere manier plaats te vinden.
A19: kriho | B19: 1001 | C19: Zwemplas Krimpenerhout | E19: Zoop stoppen als effecten peilfluctuatie duidelijk zijn | F19: Metingen op K_0111 en K_1112 in 2025 nog doorzetten, daarna stoppen | I19: Fluoroprobe toegevoegd op K_1111 | K19: 6891
A20: bl_zoom | B20: 1002 | C20: Maatregelen Bleiswijkse Zoom | E20: Nog even doormeten ivm ruimtelijke verschillen en afspoeling m.n. bij s_0124 | K20: 5382
A21: vegvlk_krh | B21: 1004 | C21: Vlakdekkende vegetatieopnamen Krimpenerhout | K21: 570
A22: vegvlk_blz | B22: 1005 | C22: Vlakdekkende vegetatieopnamen Bleiswijkse Zoom | K22: 1200
A23: project_kp | B23: 1006 | C23: Project Kralingse Plas | E23: grotendeels gestopt | F23: Na 2025 hopelijk stoppen | K23: 4623
A24: defos_kp | B24: 1007 | C24: Defosfatering Kralingse Plas | I24: Rekening houden met eventuele (tijdelijke) verplaatsing van de defos; overlap tussen pakket defos en basis_pakketten (weggefilterd in code) | K24: 3053
A25: zhp_diep | B25: 1008 | C25: Diepe metingen Zevenhuizerplas | K25: 1080
A26: ebpark | B26: 1011 | C26: Essenburgpark | D26: TRUE | H26: stopt | I26: Fluoroprobe toegevoegd
A27: a13a16 | B27: 1012 | C27: Aanleg verbinding A13-A16 | D27: TRUE | I27: kerkhof
A28: balg_kriwa | B28: 1013 | C28: Blauwalg Krimpenerwaard | D28: TRUE | I28: Fluoroprobe is opgenomen in de basis en roulerende meetnetten
A29: pfas | B29: 1014 | C29: Screening PFAS | D29: TRUE | I29: kerkhof
A30: ontw_zpp | B30: 1015 | C30: Woningbouw Zuidplaspolder | D30: TRUE | H30: stopt
A31: w_gouwe | B31: 1016 | C31: Woningbouw Westergouwe | D31: TRUE | I31: roulerend meetpunt geworden
A32: scr_gbm | B32: 1017 | C32: Screening Gewasbeschermingsmiddelen | D32: TRUE | I32: kerkhof
A33: peil_nesse | B33: 1018 | C33: Aangepaste peilbeheer polder de Nesse | D33: TRUE | I33: kerkhof
A34: blz_plankt | B34: 1019 | C34: Fytoplankton en zooplankton Bleiswijkse Zoom | D34: TRUE | I34: bestaat niet meer
A35: edp | B35: 1009 | C35: Eendragtspolder | D35: TRUE | F35: Na 2025 alleen nog in roulerend meetnet | I35: Fluoroprobe toegevoegd | K35: 1541
A36: leuvehaven | B36: 1020 | C36: Inlaat Leuvehaven | D36: TRUE
A37: kr_proef | B37: 1021 | C37: Onderzoek effectiviteit wegvangen kreeften | D37: TRUE | I37: Opzetten van vegetatie onderzoek?
A38: plassen_fl | B38: 1022 | C38: Fluoroprobe in plassen | D38: TRUE | I38: Fluoroprobe is opgenomen in de basis en roulerende meetnetten
A39: edp_defos | B39: 1010 | C39: Defosfatering Eendragtspolder | E39: Locatie na defos toegevoegd | H39: Nog een plan toevoegen om de werking van de defosfatering te evalueren | I39: Nog een plan toevoegen om de werking van de defosfatering te evalueren | K39: 846
A40: schollebos | B40: 1024 | C40: Herinrichting Schollebos | D40: TRUE
...

Sheet meetnetten
A1: meetnet_nr | B1: meetnet_omschrijving | C1: meetnet_code | D1: meetpunt_code | E1: artikelgroep_code | F1: frequentie_code | G1: roulerend | H1: meetjaar_code | I1: meetjaar | J1: actief | K1: datum_begin | L1: datum_eind | M1: aquon | N1: opmerkingen | O1: Opletten bij meetvraag
A2: =IFERROR(VLOOKUP($C2,meetnetcodes!$A:$C,2,FALSE),"") -> 1 | B2: =IFERROR(VLOOKUP(C2,meetnetcodes!$A:$C,3,FALSE),"") -> Basis meetnet | C2: basis | D2: K_0222 | E2: basis | F2: 12_m | G2: FALSE | I2: =IF(H2="","",YEAR(TODAY()) - MOD(YEAR(TODAY()),3) + H2 + 3) | J2: TRUE
A3: =IFERROR(VLOOKUP($C3,meetnetcodes!$A:$C,2,FALSE),"") -> 1 | B3: =IFERROR(VLOOKUP(C3,meetnetcodes!$A:$C,3,FALSE),"") -> Basis meetnet | C3: basis | D3: K_0222 | E3: coord | F3: 1_jan | G3: FALSE | J3: TRUE | K3: 44562
A4: =IFERROR(VLOOKUP($C4,meetnetcodes!$A:$C,2,FALSE),"") -> 1 | B4: =IFERROR(VLOOKUP(C4,meetnetcodes!$A:$C,3,FALSE),"") -> Basis meetnet | C4: basis | D4: K_0222 | E4: diepte_foto | F4: 1_mei | G4: FALSE | I4: =IF(H4="","",YEAR(TODAY()) - MOD(YEAR(TODAY()),3) + H4 + 3) | J4: TRUE
A5: =IFERROR(VLOOKUP($C5,meetnetcodes!$A:$C,2,FALSE),"") -> 1 | B5: =IFERROR(VLOOKUP(C5,meetnetcodes!$A:$C,3,FALSE),"") -> Basis meetnet | C5: basis | D5: K_0222 | E5: fluoroprobe | F5: 6_m_zomer | G5: FALSE | I5: =IF(H5="","",YEAR(TODAY()) - MOD(YEAR(TODAY()),3) + H5 + 3) | J5: TRUE | K5: 44562
A6: =IFERROR(VLOOKUP($C6,meetnetcodes!$A:$C,2,FALSE),"") -> 1 | B6: =IFERROR(VLOOKUP(C6,meetnetcodes!$A:$C,3,FALSE),"") -> Basis meetnet | C6: basis | D6: K_0301 | E6: basis | F6: 12_m | G6: FALSE | I6: =IF(H6="","",YEAR(TODAY()) - MOD(YEAR(TODAY()),3) + H6 + 3) | J6: TRUE
A7: =IFERROR(VLOOKUP($C7,meetnetcodes!$A:$C,2,FALSE),"") -> 1 | B7: =IFERROR(VLOOKUP(C7,meetnetcodes!$A:$C,3,FALSE),"") -> Basis meetnet | C7: basis | D7: K_0301 | E7: coord | F7: 1_jan | G7: FALSE | J7: TRUE | K7: 44562
A8: =IFERROR(VLOOKUP($C8,meetnetcodes!$A:$C,2,FALSE),"") -> 1 | B8: =IFERROR(VLOOKUP(C8,meetnetcodes!$A:$C,3,FALSE),"") -> Basis meetnet | C8: basis | D8: K_0301 | E8: diepte_foto | F8: 1_mei | G8: FALSE | I8: =IF(H8="","",YEAR(TODAY()) - MOD(YEAR(TODAY()),3) + H8 + 3) | J8: TRUE
A9: =IFERROR(VLOOKUP($C9,meetnetcodes!$A:$C,2,FALSE),"") -> 1 | B9: =IFERROR(VLOOKUP(C9,meetnetcodes!$A:$C,3,FALSE),"") -> Basis meetnet | C9: basis | D9: K_0301 | E9: fluoroprobe | F9: 6_m_zomer | G9: FALSE | I9: =IF(H9="","",YEAR(TODAY()) - MOD(YEAR(TODAY()),3) + H9 + 3) | J9: TRUE | K9: 44562
A10: =IFERROR(VLOOKUP($C10,meetnetcodes!$A:$C,2,FALSE),"") -> 1 | B10: =IFERROR(VLOOKUP(C10,meetnetcodes!$A:$C,3,FALSE),"") -> Basis meetnet | C10: basis | D10: K_0427 | E10: basis | F10: 12_m | G10: FALSE | I10: =IF(H10="","",YEAR(TODAY()) - MOD(YEAR(TODAY()),3) + H10 + 3) | J10: TRUE
A11: =IFERROR(VLOOKUP($C11,meetnetcodes!$A:$C,2,FALSE),"") -> 1 | B11: =IFERROR(VLOOKUP(C11,meetnetcodes!$A:$C,3,FALSE),"") -> Basis meetnet | C11: basis | D11: K_0427 | E11: coord | F11: 1_jan | G11: FALSE | J11: TRUE | K11: 44562
A12: =IFERROR(VLOOKUP($C12,meetnetcodes!$A:$C,2,FALSE),"") -> 1 | B12: =IFERROR(VLOOKUP(C12,meetnetcodes!$A:$C,3,FALSE),"") -> Basis meetnet | C12: basis | D12: K_0427 | E12: diepte_foto | F12: 1_mei | G12: FALSE | I12: =IF(H12="","",YEAR(TODAY()) - MOD(YEAR(TODAY()),3) + H12 + 3) | J12: TRUE
A13: =IFERROR(VLOOKUP($C13,meetnetcodes!$A:$C,2,FALSE),"") -> 1 | B13: =IFERROR(VLOOKUP(C13,meetnetcodes!$A:$C,3,FALSE),"") -> Basis meetnet | C13: basis | D13: K_0427 | E13: fluoroprobe | F13: 6_m_zomer | G13: FALSE | I13: =IF(H13="","",YEAR(TODAY()) - MOD(YEAR(TODAY()),3) + H13 + 3) | J13: TRUE | K13: 44562
A14: =IFERROR(VLOOKUP($C14,meetnetcodes!$A:$C,2,FALSE),"") -> 1 | B14: =IFERROR(VLOOKUP(C14,meetnetcodes!$A:$C,3,FALSE),"") -> Basis meetnet | C14: basis | D14: K_0801 | E14: basis | F14: 12_m | G14: FALSE | I14: =IF(H14="","",YEAR(TODAY()) - MOD(YEAR(TODAY()),3) + H14 + 3) | J14: TRUE
A15: =IFERROR(VLOOKUP($C15,meetnetcodes!$A:$C,2,FALSE),"") -> 1 | B15: =IFERROR(VLOOKUP(C15,meetnetcodes!$A:$C,3,FALSE),"") -> Basis meetnet | C15: basis | D15: K_0801 | E15: coord | F15: 1_jan | G15: FALSE | J15: TRUE | K15: 44562
A16: =IFERROR(VLOOKUP($C16,meetnetcodes!$A:$C,2,FALSE),"") -> 1 | B16: =IFERROR(VLOOKUP(C16,meetnetcodes!$A:$C,3,FALSE),"") -> Basis meetnet | C16: basis | D16: K_0801 | E16: diepte_foto | F16: 1_mei | G16: FALSE | I16: =IF(H16="","",YEAR(TODAY()) - MOD(YEAR(TODAY()),3) + H16 + 3) | J16: TRUE
A17: =IFERROR(VLOOKUP($C17,meetnetcodes!$A:$C,2,FALSE),"") -> 1 | B17: =IFERROR(VLOOKUP(C17,meetnetcodes!$A:$C,3,FALSE),"") -> Basis meetnet | C17: basis | D17: K_0801 | E17: fluoroprobe | F17: 6_m_zomer | G17: FALSE | I17: =IF(H17="","",YEAR(TODAY()) - MOD(YEAR(TODAY()),3) + H17 + 3) | J17: TRUE | K17: 44562
A18: =IFERROR(VLOOKUP($C18,meetnetcodes!$A:$C,2,FALSE),"") -> 1 | B18: =IFERROR(VLOOKUP(C18,meetnetcodes!$A:$C,3,FALSE),"") -> Basis meetnet | C18: basis | D18: K_0803 | E18: basis | F18: 12_m | G18: FALSE | I18: =IF(H18="","",YEAR(TODAY()) - MOD(YEAR(TODAY()),3) + H18 + 3) | J18: FALSE | L18: 45291 | N18: verplaatst naar roulerend meetnet ivm beperkt belang
A19: =IFERROR(VLOOKUP($C19,meetnetcodes!$A:$C,2,FALSE),"") -> 1 | B19: =IFERROR(VLOOKUP(C19,meetnetcodes!$A:$C,3,FALSE),"") -> Basis meetnet | C19: basis | D19: K_0803 | E19: coord | F19: 1_jan | G19: FALSE | J19: FALSE | K19: 44562 | L19: 45291 | N19: verplaatst naar roulerend meetnet ivm beperkt belang
A20: =IFERROR(VLOOKUP($C20,meetnetcodes!$A:$C,2,FALSE),"") -> 1 | B20: =IFERROR(VLOOKUP(C20,meetnetcodes!$A:$C,3,FALSE),"") -> Basis meetnet | C20: basis | D20: K_0803 | E20: diepte_foto | F20: 1_mei | G20: FALSE | I20: =IF(H20="","",YEAR(TODAY()) - MOD(YEAR(TODAY()),3) + H20 + 3) | J20: FALSE | L20: 45291 | N20: verplaatst naar roulerend meetnet ivm beperkt belang
A21: =IFERROR(VLOOKUP($C21,meetnetcodes!$A:$C,2,FALSE),"") -> 1 | B21: =IFERROR(VLOOKUP(C21,meetnetcodes!$A:$C,3,FALSE),"") -> Basis meetnet | C21: basis | D21: K_0803 | E21: fluoroprobe | F21: 6_m_zomer | G21: FALSE | I21: =IF(H21="","",YEAR(TODAY()) - MOD(YEAR(TODAY()),3) + H21 + 3) | J21: FALSE | K21: 44562 | L21: 45291 | N21: verplaatst naar roulerend meetnet ivm beperkt belang
A22: =IFERROR(VLOOKUP($C22,meetnetcodes!$A:$C,2,FALSE),"") -> 1 | B22: =IFERROR(VLOOKUP(C22,meetnetcodes!$A:$C,3,FALSE),"") -> Basis meetnet | C22: basis | D22: K_1035 | E22: basis | F22: 12_m | G22: FALSE | I22: =IF(H22="","",YEAR(TODAY()) - MOD(YEAR(TODAY()),3) + H22 + 3) | J22: TRUE
A23: =IFERROR(VLOOKUP($C23,meetnetcodes!$A:$C,2,FALSE),"") -> 1 | B23: =IFERROR(VLOOKUP(C23,meetnetcodes!$A:$C,3,FALSE),"") -> Basis meetnet | C23: basis | D23: K_1035 | E23: coord | F23: 1_jan | G23: FALSE | J23: TRUE | K23: 44562
A24: =IFERROR(VLOOKUP($C24,meetnetcodes!$A:$C,2,FALSE),"") -> 1 | B24: =IFERROR(VLOOKUP(C24,meetnetcodes!$A:$C,3,FALSE),"") -> Basis meetnet | C24: basis | D24: K_1035 | E24: diepte_foto | F24: 1_mei | G24: FALSE | I24: =IF(H24="","",YEAR(TODAY()) - MOD(YEAR(TODAY()),3) + H24 + 3) | J24: TRUE
A25: =IFERROR(VLOOKUP($C25,meetnetcodes!$A:$C,2,FALSE),"") -> 1 | B25: =IFERROR(VLOOKUP(C25,meetnetcodes!$A:$C,3,FALSE),"") -> Basis meetnet | C25: basis | D25: K_1035 | E25: fluoroprobe | F25: 6_m_zomer | G25: FALSE | I25: =IF(H25="","",YEAR(TODAY()) - MOD(YEAR(TODAY()),3) + H25 + 3) | J25: TRUE | K25: 44562
A26: =IFERROR(VLOOKUP($C26,meetnetcodes!$A:$C,2,FALSE),"") -> 1 | B26: =IFERROR(VLOOKUP(C26,meetnetcodes!$A:$C,3,FALSE),"") -> Basis meetnet | C26: basis | D26: RWS_0108 | E26: basis_zwevend | F26: 12_m | G26: FALSE | I26: =IF(H26="","",YEAR(TODAY()) - MOD(YEAR(TODAY()),3) + H26 + 3) | J26: TRUE | K26: 43922 | N26: o.a. toegevoegd ivm doorvoer Krimpenerwaard
A27: =IFERROR(VLOOKUP($C27,meetnetcodes!$A:$C,2,FALSE),"") -> 1 | B27: =IFERROR(VLOOKUP(C27,meetnetcodes!$A:$C,3,FALSE),"") -> Basis meetnet | C27: basis | D27: RWS_0108 | E27: coord | F27: 1_jan | G27: FALSE | J27: TRUE | K27: 44562
A28: =IFERROR(VLOOKUP($C28,meetnetcodes!$A:$C,2,FALSE),"") -> 1 | B28: =IFERROR(VLOOKUP(C28,meetnetcodes!$A:$C,3,FALSE),"") -> Basis meetnet | C28: basis | D28: RWS_0108 | E28: diepte_foto | F28: 1_mei | G28: FALSE | I28: =IF(H28="","",YEAR(TODAY()) - MOD(YEAR(TODAY()),3) + H28 + 3) | J28: TRUE | K28: 43922 | N28: o.a. toegevoegd ivm doorvoer Krimpenerwaard
A29: =IFERROR(VLOOKUP($C29,meetnetcodes!$A:$C,2,FALSE),"") -> 1 | B29: =IFERROR(VLOOKUP(C29,meetnetcodes!$A:$C,3,FALSE),"") -> Basis meetnet | C29: basis | D29: RWS_0108 | E29: fluoroprobe | F29: 6_m_zomer | G29: FALSE | I29: =IF(H29="","",YEAR(TODAY()) - MOD(YEAR(TODAY()),3) + H29 + 3) | J29: FALSE | K29: 44562 | L29: 44926
A30: =IFERROR(VLOOKUP($C30,meetnetcodes!$A:$C,2,FALSE),"") -> 1 | B30: =IFERROR(VLOOKUP(C30,meetnetcodes!$A:$C,3,FALSE),"") -> Basis meetnet | C30: basis | D30: RWS_0112 | E30: basis_zwevend | F30: 12_m | G30: FALSE | I30: =IF(H30="","",YEAR(TODAY()) - MOD(YEAR(TODAY()),3) + H30 + 3) | J30: TRUE
A31: =IFERROR(VLOOKUP($C31,meetnetcodes!$A:$C,2,FALSE),"") -> 1 | B31: =IFERROR(VLOOKUP(C31,meetnetcodes!$A:$C,3,FALSE),"") -> Basis meetnet | C31: basis | D31: RWS_0112 | E31: coord | F31: 1_jan | G31: FALSE | J31: TRUE | K31: 44562
A32: =IFERROR(VLOOKUP($C32,meetnetcodes!$A:$C,2,FALSE),"") -> 1 | B32: =IFERROR(VLOOKUP(C32,meetnetcodes!$A:$C,3,FALSE),"") -> Basis meetnet | C32: basis | D32: RWS_0112 | E32: diepte_foto | F32: 1_mei | G32: FALSE | I32: =IF(H32="","",YEAR(TODAY()) - MOD(YEAR(TODAY()),3) + H32 + 3) | J32: TRUE
A33: =IFERROR(VLOOKUP($C33,meetnetcodes!$A:$C,2,FALSE),"") -> 1 | B33: =IFERROR(VLOOKUP(C33,meetnetcodes!$A:$C,3,FALSE),"") -> Basis meetnet | C33: basis | D33: RWS_0112 | E33: fluoroprobe | F33: 6_m_zomer | G33: FALSE | I33: =IF(H33="","",YEAR(TODAY()) - MOD(YEAR(TODAY()),3) + H33 + 3) | J33: FALSE | K33: 44562 | L33: 44926
A34: =IFERROR(VLOOKUP($C34,meetnetcodes!$A:$C,2,FALSE),"") -> 1 | B34: =IFERROR(VLOOKUP(C34,meetnetcodes!$A:$C,3,FALSE),"") -> Basis meetnet | C34: basis | D34: RWS_0113 | E34: basis_zwevend | F34: 12_m | G34: FALSE | I34: =IF(H34="","",YEAR(TODAY()) - MOD(YEAR(TODAY()),3) + H34 + 3) | J34: TRUE | K34: 44044 | N34: Nieuw basismeetpunt ivm inlaat Leuvehaven
A35: =IFERROR(VLOOKUP($C35,meetnetcodes!$A:$C,2,FALSE),"") -> 1 | B35: =IFERROR(VLOOKUP(C35,meetnetcodes!$A:$C,3,FALSE),"") -> Basis meetnet | C35: basis | D35: RWS_0113 | E35: coord | F35: 1_jan | G35: FALSE | J35: TRUE | K35: 44562
A36: =IFERROR(VLOOKUP($C36,meetnetcodes!$A:$C,2,FALSE),"") -> 1 | B36: =IFERROR(VLOOKUP(C36,meetnetcodes!$A:$C,3,FALSE),"") -> Basis meetnet | C36: basis | D36: RWS_0113 | E36: diepte_foto | F36: 1_mei | G36: FALSE | I36: =IF(H36="","",YEAR(TODAY()) - MOD(YEAR(TODAY()),3) + H36 + 3) | J36: TRUE | K36: 44044 | N36: Nieuw basismeetpunt ivm inlaat Leuvehaven
A37: =IFERROR(VLOOKUP($C37,meetnetcodes!$A:$C,2,FALSE),"") -> 1 | B37: =IFERROR(VLOOKUP(C37,meetnetcodes!$A:$C,3,FALSE),"") -> Basis meetnet | C37: basis | D37: RWS_0113 | E37: fluoroprobe | F37: 6_m_zomer | G37: FALSE | I37: =IF(H37="","",YEAR(TODAY()) - MOD(YEAR(TODAY()),3) + H37 + 3) | J37: FALSE | K37: 44562 | L37: 44926
A38: =IFERROR(VLOOKUP($C38,meetnetcodes!$A:$C,2,FALSE),"") -> 1 | B38: =IFERROR(VLOOKUP(C38,meetnetcodes!$A:$C,3,FALSE),"") -> Basis meetnet | C38: basis | D38: RWS_0114 | E38: basis_zwevend | F38: 12_m | G38: FALSE | I38: =IF(H38="","",YEAR(TODAY()) - MOD(YEAR(TODAY()),3) + H38 + 3) | J38: TRUE | K38: 44317
A39: =IFERROR(VLOOKUP($C39,meetnetcodes!$A:$C,2,FALSE),"") -> 1 | B39: =IFERROR(VLOOKUP(C39,meetnetcodes!$A:$C,3,FALSE),"") -> Basis meetnet | C39: basis | D39: RWS_0114 | E39: coord | F39: 1_jan | G39: FALSE | I39: =IF(H39="","",YEAR(TODAY()) - MOD(YEAR(TODAY()),3) + H39 + 3) | J39: TRUE | K39: 44317
A40: =IFERROR(VLOOKUP($C40,meetnetcodes!$A:$C,2,FALSE),"") -> 1 | B40: =IFERROR(VLOOKUP(C40,meetnetcodes!$A:$C,3,FALSE),"") -> Basis meetnet | C40: basis | D40: RWS_0114 | E40: diepte_foto | F40: 1_mei | G40: FALSE | I40: =IF(H40="","",YEAR(TODAY()) - MOD(YEAR(TODAY()),3) + H40 + 3) | J40: TRUE | K40: 44317
...

Sheet artikelgroepcodes
A1: artikelgroep_code | B1: artikelgroep_omschrijving | C1: Opmerkingen
A2: admin | B2: Administratie en locatiebezoek
A3: admin_boot | B3: Administratie en locatiebezoek boot
A4: barium_nf | B4: Barium na filtratie
A5: basis | B5: Basispakket veldmetingen en nutriënten
A6: basis_boot | B6: Basispakket veldmetingen en nutriënten met boot
A7: basis_diep | B7: Basispakket veldmetingen en nutriënten zonder oppervlaktemetingen met boot | C7: o.a. diepe metingen ZHP
A8: basis_macro | B8: Basispakket veldmetingen, nutriënten en macro-ionen
A9: basis_visueel | B9: Basispakket veldmetingen en nutriënten met uitgebreide visuele waarnemingen
A10: basis_zwevend | B10: Basispakket veldmetingen, nutriënten en zwevende bestanddelen
A11: basis_zwevend_boot | B11: Basispakket veldmetingen, nutriënten en zwevende bestanddelen met boot
A12: basis_zwevend_z | B12: Basispakket zwem veldmetingen, nutriënten en zwevende bestanddelen | C12: alleen voor zwemlocatie ivm overlap zwemwaterpakket
A13: blauwalg_biovolume | B13: Biovolume blauwalgen
A14: coord | B14: RD-coordinaten
A15: defos | B15: Metingen voor het functioneren van de defosfatering | C15: o.a. defosfatering KP
A16: diat | B16: Diatomeeën
A17: diepte_foto | B17: Dieptebepaling en een foto
A18: diepteprofiel | B18: Bepaling diepteprofiel | C18: altijd icm een gewoon oppervlaktemonster
A19: fluoroprobe | B19: Fluoroprobemeting
A20: fosfor | B20: Totaal fosfor | C20: o.a. tbv defosfatering EDP
A21: fyto | B21: Fytoplanktononderzoek in ondiep water
A22: fyto_zoop | B22: Fyto- en zooplanktononderzoek in ondiep water
A23: fyto_zoop_diep | B23: Fyto- en zooplanktononderzoek in diep water
A24: gbm_b | B24: Bestrijdingsmiddelenpakket B
A25: gbm_cd | B25: Bestrijdingsmiddelenpakket C en D
A26: gbm_cfcz | B26: Bestrijdingsmiddelenpakket CFCZ
A27: gbm_d | B27: Bestrijdingsmiddelenpakket D
A28: gbm_glas | B28: Bestrijdingsmiddelenpakket LMGBM Glastuinbouw (extern)
A29: gbm_neg | B29: Bestrijdingsmiddelenpakket negatief | C29: vervangt cfcz
A30: ijking_egv | B30: Metingen tbv ijking van EGV meters
A31: ijzer | B31: IJzer
A32: kreeften | B32: Kreeften met 12 korven
A33: krw_metalen_2020 | B33: KRW onderzoek metalen 2020
A34: krw_metalen_2021 | B34: KRW onderzoek metalen 2021
A35: krw_metalen_2022 | B35: KRW onderzoek metalen 2022
A36: krw_metalen_zink_2021 | B36: KRW onderzoek metalen + zink 2021
A37: lanthaan | B37: lanthaan ivm toepassing Phoslock | C37: uitbesteed onderzoek
A38: mafa_lijn | B38: Macrofauna in lijnvormig water
A39: mafa_plas | B39: Macrofauna in meren en plassen
A40: mafy_100 | B40: Macrofyten 100 m | C40: KRW
...

Sheet artikelgroepen
A1: artikelgroep_code | B1: artikelgroep_omschrijving | C1: artikel_naam | D1: datum_uit_gebruik | E1: opmerkingen
A2: admin | B2: =IFERROR(VLOOKUP(A2,artikelgroepcodes!$A:$B,2,FALSE),"") -> Administratie en locatiebezoek | C2: administratie
A3: admin | B3: =IFERROR(VLOOKUP(A3,artikelgroepcodes!$A:$B,2,FALSE),"") -> Administratie en locatiebezoek | C3: locatiebezoek
A4: admin_boot | B4: =IFERROR(VLOOKUP(A4,artikelgroepcodes!$A:$B,2,FALSE),"") -> Administratie en locatiebezoek boot | C4: administratie
A5: admin_boot | B5: =IFERROR(VLOOKUP(A5,artikelgroepcodes!$A:$B,2,FALSE),"") -> Administratie en locatiebezoek boot | C5: locatiebezoek boot
A6: barium_nf | B6: =IFERROR(VLOOKUP(A6,artikelgroepcodes!$A:$B,2,FALSE),"") -> Barium na filtratie | C6: administratie
A7: barium_nf | B7: =IFERROR(VLOOKUP(A7,artikelgroepcodes!$A:$B,2,FALSE),"") -> Barium na filtratie | C7: barium nf
A8: barium_nf | B8: =IFERROR(VLOOKUP(A8,artikelgroepcodes!$A:$B,2,FALSE),"") -> Barium na filtratie | C8: filtratie metalen
A9: barium_nf | B9: =IFERROR(VLOOKUP(A9,artikelgroepcodes!$A:$B,2,FALSE),"") -> Barium na filtratie | C9: locatiebezoek
A10: barium_nf | B10: =IFERROR(VLOOKUP(A10,artikelgroepcodes!$A:$B,2,FALSE),"") -> Barium na filtratie | C10: steekbemonstering
A11: barium_nf | B11: =IFERROR(VLOOKUP(A11,artikelgroepcodes!$A:$B,2,FALSE),"") -> Barium na filtratie | C11: voorbehandeling metalen nf
A12: basis | B12: =IFERROR(VLOOKUP(A12,artikelgroepcodes!$A:$B,2,FALSE),"") -> Basispakket veldmetingen en nutriënten | C12: administratie
A13: basis | B13: =IFERROR(VLOOKUP(A13,artikelgroepcodes!$A:$B,2,FALSE),"") -> Basispakket veldmetingen en nutriënten | C13: filtratie nutriënten
... A33: basis_macro | B33: =IFERROR(VLOOKUP(A33,artikelgroepcodes!$A:$B,2,FALSE),"") -> Basispakket veldmetingen, nutriënten en macro-ionen | C33: ijs
A34: basis_macro | B34: =IFERROR(VLOOKUP(A34,artikelgroepcodes!$A:$B,2,FALSE),"") -> Basispakket veldmetingen, nutriënten en macro-ionen | C34: kroos | E34: kroos zit in geen van beide pakketten
A35: basis_macro | B35: =IFERROR(VLOOKUP(A35,artikelgroepcodes!$A:$B,2,FALSE),"") -> Basispakket veldmetingen, nutriënten en macro-ionen | C35: locatiebezoek
A36: basis_macro | B36: =IFERROR(VLOOKUP(A36,artikelgroepcodes!$A:$B,2,FALSE),"") -> Basispakket veldmetingen, nutriënten en macro-ionen | C36: pakket nutrienten en macro-ionen
A37: basis_macro | B37: =IFERROR(VLOOKUP(A37,artikelgroepcodes!$A:$B,2,FALSE),"") -> Basispakket veldmetingen, nutriënten en macro-ionen | C37: pakket veldmetingen
A38: basis_macro | B38: =IFERROR(VLOOKUP(A38,artikelgroepcodes!$A:$B,2,FALSE),"") -> Basispakket veldmetingen, nutriënten en macro-ionen | C38: steekbemonstering
A39: basis_macro | B39: =IFERROR(VLOOKUP(A39,artikelgroepcodes!$A:$B,2,FALSE),"") -> Basispakket veldmetingen, nutriënten en macro-ionen | C39: voorbehandeling metalen nf
A40: basis_visueel | B40: =IFERROR(VLOOKUP(A40,artikelgroepcodes!$A:$B,2,FALSE),"") -> Basispakket veldmetingen en nutriënten met uitgebreide visuele waarnemingen | C40: administratie | E40: Gelijk aan artikelgroep basis door gebruik van POWMETSUB (Overall pakket incl waarnemingen)
A41: basis_visueel | B41: =IFERROR(VLOOKUP(A41,artikelgroepcodes!$A:$B,2,FALSE),"") -> Basispakket veldmetingen en nutriënten met uitgebreide visuele waarnemingen | C41: filtratie nutriënten | E41: Gelijk aan artikelgroep basis door gebruik van POWMETSUB (Overall pakket incl waarnemingen)
A42: basis_visueel | B42: =IFERROR(VLOOKUP(A42,artikelgroepcodes!$A:$B,2,FALSE),"") -> Basispakket veldmetingen en nutriënten met uitgebreide visuele waarnemingen | C42: ijs | E42: Gelijk aan artikelgroep basis door gebruik van POWMETSUB (Overall pakket incl waarnemingen)
A43: basis_visueel | B43: =IFERROR(VLOOKUP(A43,artikelgroepcodes!$A:$B,2,FALSE),"") -> Basispakket veldmetingen en nutriënten met uitgebreide visuele waarnemingen | C43: locatiebezoek | E43: Gelijk aan artikelgroep basis door gebruik van POWMETSUB (Overall pakket incl waarnemingen)
A44: basis_visueel | B44: =IFERROR(VLOOKUP(A44,artikelgroepcodes!$A:$B,2,FALSE),"") -> Basispakket veldmetingen en nutriënten met uitgebreide visuele waarnemingen | C44: pakket nutrienten veldmetingen waarnemingen | E44: Gelijk aan artikelgroep basis door gebruik van POWMETSUB (Overall pakket incl waarnemingen)
A45: basis_visueel | B45: =IFERROR(VLOOKUP(A45,artikelgroepcodes!$A:$B,2,FALSE),"") -> Basispakket veldmetingen en nutriënten met uitgebreide visuele waarnemingen | C45: steekbemonstering | E45: Gelijk aan artikelgroep basis door gebruik van POWMETSUB (Overall pakket incl waarnemingen)
A46: basis_zwevend | B46: =IFERROR(VLOOKUP(A46,artikelgroepcodes!$A:$B,2,FALSE),"") -> Basispakket veldmetingen, nutriënten en zwevende bestanddelen | C46: administratie
A47: basis_zwevend | B47: =IFERROR(VLOOKUP(A47,artikelgroepcodes!$A:$B,2,FALSE),"") -> Basispakket veldmetingen, nutriënten en zwevende bestanddelen | C47: chlorofyl
A48: basis_zwevend | B48: =IFERROR(VLOOKUP(A48,artikelgroepcodes!$A:$B,2,FALSE),"") -> Basispakket veldmetingen, nutriënten en zwevende bestanddelen | C48: filtratie nutriënten
A49: basis_zwevend | B49: =IFERROR(VLOOKUP(A49,artikelgroepcodes!$A:$B,2,FALSE),"") -> Basispakket veldmetingen, nutriënten en zwevende bestanddelen | C49: ijs
A50: basis_zwevend | B50: =IFERROR(VLOOKUP(A50,artikelgroepcodes!$A:$B,2,FALSE),"") -> Basispakket veldmetingen, nutriënten en zwevende bestanddelen | C50: locatiebezoek
A51: basis_zwevend | B51: =IFERROR(VLOOKUP(A51,artikelgroepcodes!$A:$B,2,FALSE),"") -> Basispakket veldmetingen, nutriënten en zwevende bestanddelen | C51: onopgeloste stoffen
A52: basis_zwevend | B52: =IFERROR(VLOOKUP(A52,artikelgroepcodes!$A:$B,2,FALSE),"") -> Basispakket veldmetingen, nutriënten en zwevende bestanddelen | C52: pakket nutrienten veldmetingen waarnemingen
A53: basis_zwevend | B53: =IFERROR(VLOOKUP(A53,artikelgroepcodes!$A:$B,2,FALSE),"") -> Basispakket veldmetingen, nutriënten en zwevende bestanddelen | C53: steekbemonstering
A54: basis_zwevend_boot | B54: =IFERROR(VLOOKUP(A54,artikelgroepcodes!$A:$B,2,FALSE),"") -> Basispakket veldmetingen, nutriënten en zwevende bestanddelen met boot | C54: administratie
A55: basis_zwevend_boot | B55: =IFERROR(VLOOKUP(A55,artikelgroepcodes!$A:$B,2,FALSE),"") -> Basispakket veldmetingen, nutriënten en zwevende bestanddelen met boot | C55: chlorofyl
A56: basis_zwevend_boot | B56: =IFERROR(VLOOKUP(A56,artikelgroepcodes!$A:$B,2,FALSE),"") -> Basispakket veldmetingen, nutriënten en zwevende bestanddelen met boot | C56: filtratie nutriënten
A57: basis_zwevend_boot | B57: =IFERROR(VLOOKUP(A57,artikelgroepcodes!$A:$B,2,FALSE),"") -> Basispakket veldmetingen, nutriënten en zwevende bestanddelen met boot | C57: ijs
... A72: defos | B72: =IFERROR(VLOOKUP(A72,artikelgroepcodes!$A:$B,2,FALSE),"") -> Metingen voor het functioneren van de defosfatering | C72: administratie
A73: defos | B73: =IFERROR(VLOOKUP(A73,artikelgroepcodes!$A:$B,2,FALSE),"") -> Metingen voor het functioneren van de defosfatering | C73: TOC | E73: Was CZV maar CZV wordt uigefaseerd
...

Sheet artikelen
A1: artikel_naam | B1: artikel_omschrijving | C1: artikel_code | D1: analyse_aquon | E1: artikel_verkooppunten | F1: artikel_opmerking | G1: artikel_inhoudelijk | H1: artikel_hybi
A2: administratie | B2: Administratie per monster | C2: 7ADMINK01|OW_ADMINK | D2: =IFERROR(VLOOKUP(C2,pdc_ow!$C:$D,2,FALSE),"") | E2: 5 | G2: FALSE | H2: FALSE
A3: administratie extern | B3: Administratie t.b.v. uitbesteed onderzoek per monster | C3: 7ADMEXT01|OW_ADMEXT | D3: =IFERROR(VLOOKUP(C3,pdc_ow!$C:$D,2,FALSE),"") | E3: 7 | G3: FALSE | H3: FALSE
A4: arseen nf | B4: Arseen opgelost | C4: 3MET05|OW_ASNF | D4: =IFERROR(VLOOKUP(C4,pdc_ow!$C:$D,2,FALSE),"") -> OW Metalen opgelost | E4: =VLOOKUP(C4,pdc_ow!$C:$F,4,FALSE) -> 6 | G4: TRUE | H4: FALSE
A5: barium nf | B5: Barium opgelost | C5: 3MET05|OW_BANF | D5: =IFERROR(VLOOKUP(C5,pdc_ow!$C:$D,2,FALSE),"") -> OW Metalen opgelost | E5: =VLOOKUP(C5,pdc_ow!$C:$F,4,FALSE) -> 6 | G5: TRUE | H5: FALSE
A6: bemonstering fytoplankton diep | B6: Bemonstering Fytoplankton diep | C6: 7BMFYTDP01|OW_BMFYTDP | D6: =IFERROR(VLOOKUP(C6,pdc_ow!$C:$D,2,FALSE),"") -> OW Fytoplankton bemonstering (diepe meren/plassen) | E6: =VLOOKUP(C6,pdc_ow!$C:$F,4,FALSE) -> 53 | G6: FALSE | H6: FALSE
A7: bemonstering fytoplankton ondiep | B7: Bemonstering Fytoplankton ondiep | C7: 7BMFYTON01|OW_BMFYTON | D7: =IFERROR(VLOOKUP(C7,pdc_ow!$C:$D,2,FALSE),"") -> OW Fytoplankton bemonstering (sloten, kanalen, ondiepe meren/plassen) | E7: =VLOOKUP(C7,pdc_ow!$C:$F,4,FALSE) -> 4 | G7: FALSE | H7: FALSE
A8: bemonstering zooplankton diep | B8: Bemonstering Zooplankton diep | C8: 7BMZOODP01|OW_BMZOODP | D8: =IFERROR(VLOOKUP(C8,pdc_ow!$C:$D,2,FALSE),"") -> OW Zoöplankton bemonstering (diepe meren/plassen) | E8: =VLOOKUP(C8,pdc_ow!$C:$F,4,FALSE) -> 53 | G8: FALSE | H8: FALSE
A9: bemonstering zooplankton ondiep | B9: Bemonstering Zooplankton ondiep | C9: 7BMZOOON01|OW_BMZOOON | D9: =IFERROR(VLOOKUP(C9,pdc_ow!$C:$D,2,FALSE),"") -> OW Zoöplankton bemonstering (sloten, kanalen, ondiepe meren/plassen) | E9: =VLOOKUP(C9,pdc_ow!$C:$F,4,FALSE) -> 4 | G9: FALSE | H9: FALSE
A10: bemonsteringsdiepte | B10: bemonsteringsdiepte | C10: 7BEMDIEP01|OW_BEMDIEP | D10: =IFERROR(VLOOKUP(C10,pdc_ow!$C:$D,2,FALSE),"") -> OW Bemonsteringsdiepte | E10: =VLOOKUP(C10,pdc_ow!$C:$F,4,FALSE) -> 1 | G10: TRUE | H10: FALSE
A11: calcium nf | B11: Calcium opgelost | C11: 3MET05|OW_CANF | D11: =IFERROR(VLOOKUP(C11,pdc_ow!$C:$D,2,FALSE),"") -> OW Metalen opgelost | E11: =VLOOKUP(C11,pdc_ow!$C:$F,4,FALSE) -> 6 | G11: TRUE | H11: FALSE
A12: chloride | B12: Chloride | C12: 2NUTR05|OW_CLNF | D12: =IFERROR(VLOOKUP(C12,pdc_ow!$C:$D,2,FALSE),"") -> OW Nutriënten | E12: =VLOOKUP(C12,pdc_ow!$C:$F,4,FALSE) -> 7 | G12: TRUE | H12: FALSE
A13: chlorofyl | B13: Chlorofyl-a | C13: 2CHLOROF01|OW_CHLFA | D13: =IFERROR(VLOOKUP(C13,pdc_ow!$C:$D,2,FALSE),"") -> OW Chlorofyl, Faeofytine | E13: =VLOOKUP(C13,pdc_ow!$C:$F,4,FALSE) -> 21 | G13: TRUE | H13: FALSE
A14: coordinaten | B14: RD-coordinaten | C14: 7COORD01|OW_COORD | D14: =IFERROR(VLOOKUP(C14,pdc_ow!$C:$D,2,FALSE),"") -> OW X,Y coordinaat | E14: =VLOOKUP(C14,pdc_ow!$C:$F,4,FALSE) -> 2 | G14: TRUE | H14: FALSE
A15: CZV | B15: Chemisch zuurstofverbruik | C15: 3CZVCUV01|OW_CZVO2 | D15: =IFERROR(VLOOKUP(C15,pdc_ow!$C:$D,2,FALSE),"") -> OW Chemisch Zuurstofverbruik Cuvettentest | E15: =VLOOKUP(C15,pdc_ow!$C:$F,4,FALSE) -> 13 | G15: TRUE | H15: FALSE
... A17: diatomeeën monstername | B17: Bentische diatomeeën, routine monstername | C17: 5BDRMON01|OW_BDRMON | D17: =IFERROR(VLOOKUP(C17,pdc_ow!$C:$D,2,FALSE),"") -> OW Bentische diatomeeën, routine monstername | E17: =VLOOKUP(C17,pdc_ow!$C:$F,4,FALSE) -> 58 | G17: FALSE | H17: TRUE
A18: diverse radioactiviteitsparameters | B18: Diverse radioactiviteitsparameters | C18: NVT | D18: =IFERROR(VLOOKUP(C18,pdc_ow!$C:$D,2,FALSE),"") | G18: TRUE | H18: FALSE
A19: DOC | B19: DOC - opgelost organisch koolstof | C19: 3DOC01|OW_DOC | D19: =IFERROR(VLOOKUP(C19,pdc_ow!$C:$D,2,FALSE),"") -> OW DOC | E19: =VLOOKUP(C19,pdc_ow!$C:$F,4,FALSE) -> 21 | G19: TRUE | H19: FALSE
A20: feofytine | B20: Feofytine a | C20: 2CHLOROF01|OW_FEOA | D20: =IFERROR(VLOOKUP(C20,pdc_ow!$C:$D,2,FALSE),"") -> OW Chlorofyl, Faeofytine | E20: =VLOOKUP(C20,pdc_ow!$C:$F,4,FALSE) -> 4 | G20: TRUE | H20: FALSE
A21: filtratie metalen | B21: Filtratie 0,45 µm, metalen, DOC | C21: 7FILGRT01|OW_FILGRT | D21: =IFERROR(VLOOKUP(C21,pdc_ow!$C:$D,2,FALSE),"") -> OW Filtratie 0.45 µm, Groot | E21: =VLOOKUP(C21,pdc_ow!$C:$F,4,FALSE) -> 9 | G21: FALSE | H21: FALSE
A22: filtratie nutriënten | B22: Filtratie 0,45 µm, czv-nutriënten | C22: 7FILKLN01|OW_FILKLN | D22: =IFERROR(VLOOKUP(C22,pdc_ow!$C:$D,2,FALSE),"") -> OW Filtratie 0.45 µm, Klein | E22: =VLOOKUP(C22,pdc_ow!$C:$F,4,FALSE) -> 4 | G22: FALSE | H22: FALSE
A23: fluoroprobe | B23: Blauwalgen fluoroprobemeting | C23: 2BLAUWPR01|OW_FLUOROPROBE | D23: =IFERROR(VLOOKUP(C23,pdc_ow!$C:$D,2,FALSE),"") -> OW Algemeen fluoroprobemeting | E23: =VLOOKUP(C23,pdc_ow!$C:$F,4,FALSE) -> 21 | G23: TRUE | H23: FALSE
A24: fosfor totaal | B24: Fosfor totaal | C24: 3TP01|OW_PTOTP | D24: =IFERROR(VLOOKUP(C24,pdc_ow!$C:$D,2,FALSE),"") -> OW Fosfor totaal | E24: =VLOOKUP(C24,pdc_ow!$C:$F,4,FALSE) -> 13 | G24: TRUE | H24: FALSE
A25: fosfor totaal nf | B25: Fosfor totaal na filtratie | C25: 3TP05|OW_PTOTPNF | D25: =IFERROR(VLOOKUP(C25,pdc_ow!$C:$D,2,FALSE),"") -> OW Fosfor totaal na filtratie | E25: =VLOOKUP(C25,pdc_ow!$C:$F,4,FALSE) -> 13 | G25: TRUE | H25: FALSE
A26: foto | B26: Foto | C26: 7FOTOVP01|OW_FOTO | D26: =IFERROR(VLOOKUP(C26,pdc_ow!$C:$D,2,FALSE),"") -> OW Foto verplicht | E26: =VLOOKUP(C26,pdc_ow!$C:$F,4,FALSE) -> 2 | G26: TRUE | H26: FALSE
A27: fytoplankton telling | B27: Fytoplankton telling | C27: 5FYTTEL01|OW_FYTTEL | D27: =IFERROR(VLOOKUP(C27,pdc_ow!$C:$D,2,FALSE),"") -> OW Fytoplankton telling | E27: =VLOOKUP(C27,pdc_ow!$C:$F,4,FALSE) -> 126 | G27: TRUE | H27: FALSE
A28: gbm lage grenzen analysepakket | B28: gbm lage grenzen analysepakket | C28: POWLGGBM | D28: =IFERROR(VLOOKUP(C28,pdc_ow!$C:$D,2,FALSE),"") -> OW Pakket Lage Grenzen GBM LC en GC | E28: =VLOOKUP(C28,pdc_ow!$C:$F,4,FALSE) -> 310 | G28: TRUE | H28: FALSE
A29: gbm lage grenzen voorbehandeling | B29: gbm lage grenzen voorbehandeling | C29: 3VBLGGBM01|OW_VBLGGBM | D29: =IFERROR(VLOOKUP(C29,pdc_ow!$C:$D,2,FALSE),"") -> OW Voorbewerking lage grenzen gewasbeschermingsmiddelen | E29: =VLOOKUP(C29,pdc_ow!$C:$F,4,FALSE) -> 200 | G29: FALSE | H29: FALSE
A30: geleidendheid | B30: Geleidendheid bij 25oC | C30: 7EGV01|OW_EGV | D30: =IFERROR(VLOOKUP(C30,pdc_ow!$C:$D,2,FALSE),"") -> OW EGV en temperatuur | E30: =VLOOKUP(C30,pdc_ow!$C:$F,4,FALSE) -> 3 | G30: TRUE | H30: FALSE
... A35: kobalt nf | B35: Kobalt opgelost | C35: 3MET05|OW_CONF | D35: =IFERROR(VLOOKUP(C35,pdc_ow!$C:$D,2,FALSE),"") -> OW Metalen opgelost | E35: =VLOOKUP(C35,pdc_ow!$C:$F,4,FALSE) -> 6 | G35: TRUE | H35: FALSE
A36: kreeften | B36: Kreeftenonderzoek met 12 korven | D36: =IFERROR(VLOOKUP(C36,pdc_ow!$C:$D,2,FALSE),"") | E36: 172 | F36: Niet meer via Aquon | G36: TRUE | H36: TRUE
A37: kroos | B37: Kroosbedekking | C37: 7BDKROOS01|OW_BDKROOS | D37: =IFERROR(VLOOKUP(C37,pdc_ow!$C:$D,2,FALSE),"") -> OW Bedekkingsgraad kroos | E37: =VLOOKUP(C37,pdc_ow!$C:$F,4,FALSE) -> 0 | G37: TRUE | H37: FALSE
A38: lanthaan | B38: Lanthaan | C38: 3METLA01|OW_LA | D38: =IFERROR(VLOOKUP(C38,pdc_ow!$C:$D,2,FALSE),"") -> OW Lanthaan totaal | E38: =VLOOKUP(C38,pdc_ow!$C:$F,4,FALSE) -> 27 | G38: TRUE | H38: FALSE
A39: lanthaan nf | B39: Lanthaan opgelost | C39: 3METLA05|OW_LANF | D39: =IFERROR(VLOOKUP(C39,pdc_ow!$C:$D,2,FALSE),"") -> OW Lanthaan opgelost | E39: =VLOOKUP(C39,pdc_ow!$C:$F,4,FALSE) -> 27 | G39: TRUE | H39: FALSE
A40: lithium nf | B40: Lithium na filtratie | C40: 3MET05|OW_LINF | D40: =IFERROR(VLOOKUP(C40,pdc_ow!$C:$D,2,FALSE),"") -> OW Metalen opgelost | E40: =VLOOKUP(C40,pdc_ow!$C:$F,4,FALSE) -> 6 | G40: TRUE | H40: FALSE
A41: locatiebezoek | B41: Locatiebezoek in route | C41: 7LOCBZRT01|OW_LOCBZRT | D41: =IFERROR(VLOOKUP(C41,pdc_ow!$C:$D,2,FALSE),"") -> OW Locatiebezoek in route | E41: =VLOOKUP(C41,pdc_ow!$C:$F,4,FALSE) -> 15 | G41: FALSE | H41: FALSE
A42: locatiebezoek boot | B42: Locatiebezoek met boot in route | C42: 7LOCBTRT01|OW_LOCBTRT | D42: =IFERROR(VLOOKUP(C42,pdc_ow!$C:$D,2,FALSE),"") -> OW Locatiebezoek met boot in route | E42: =VLOOKUP(C42,pdc_ow!$C:$F,4,FALSE) -> 88 | G42: FALSE | H42: FALSE
A43: macrofauna bemonstering lijnvormig | B43: macrofauna bemonstering lijnvormig | C43: 5MIRLMON01|OW_MIRLMON | D43: =IFERROR(VLOOKUP(C43,pdc_ow!$C:$D,2,FALSE),"") | E43: =VLOOKUP(C43,pdc_ow!$C:$F,4,FALSE) -> #N/A | G43: TRUE | H43: TRUE
A44: macrofauna bemonstering plassen | B44: macrofauna bemonstering plassen | C44: 5MIRPMON01|OW_MIRPMON | D44: =IFERROR(VLOOKUP(C44,pdc_ow!$C:$D,2,FALSE),"") | E44: =VLOOKUP(C44,pdc_ow!$C:$F,4,FALSE) -> #N/A | G44: TRUE | H44: TRUE
A45: macrofauna determinatie lijnvormig | B45: macrofauna determinatie lijnvormig | C45: 5MILRDET01|OW_MILRDET | D45: =IFERROR(VLOOKUP(C45,pdc_ow!$C:$D,2,FALSE),"") | E45: =VLOOKUP(C45,pdc_ow!$C:$F,4,FALSE) -> #N/A | G45: TRUE | H45: TRUE
...

Sheet pdc_ow
A1: vakgroep | B1: matrix | C1: artikel | D1: analyse | E1: componentlijst | F1: Verkoop punten | G1: component naam | H1: WNS | I1: WNS omschrijving | J1: parameter | K1: grootheid | L1: typering | M1: eenheid | N1: hoedanigheid | O1: compartiment | P1: parameter groep | Q1: waardebepalingstechniek | R1: RVA | S1: NEN_CONF | T1: NEN_NORM | U1: U_DETECTION_LIMIT | V1: CAS_NUMBER | W1: dawaco_parnr | X1: dawaco_naam
A2: Overig | B2: OW | C2: 10AQNPNT01|OW_AQNPNT | D2: OW Servicebureau AQUON-punten | E2: Servicebureau AQUON-punten | F2: 0 | R2: - | U2: 0 | W2: =IFERROR(VLOOKUP($H2,'WNS Dawaco'!$A:$C,2,FALSE),"") | X2: =IFERROR(VLOOKUP($H2,'WNS Dawaco'!$A:$C,3,FALSE),"")
A3: Overig | B3: OW | C3: 10SPOEDT01|OW_SPOEDT120 | D3: OW Spoedtoeslag | E3: Spoedtoeslag 120 punten | F3: 120 | R3: - | U3: 0 | W3: =IFERROR(VLOOKUP($H3,'WNS Dawaco'!$A:$C,2,FALSE),"") | X3: =IFERROR(VLOOKUP($H3,'WNS Dawaco'!$A:$C,3,FALSE),"")
A4: Overig | B4: OW | C4: 10SPOEDT01|OW_SPOEDT60 | D4: OW Spoedtoeslag | E4: Spoedtoeslag 60 punten | F4: 60 | R4: - | U4: 0 | W4: =IFERROR(VLOOKUP($H4,'WNS Dawaco'!$A:$C,2,FALSE),"") | X4: =IFERROR(VLOOKUP($H4,'WNS Dawaco'!$A:$C,3,FALSE),"")
A5: Fysisch Chemisch onderzoek | B5: OW | C5: 2AMMBER05|OW_AMMBER | D5: OW Ammoniak (berekend) | E5: Ammoniak (berekend) | F5: 0 | G5: ammoniak | H5: WNS6708 | I5: [] [CONCTTE] [NH3] [mg/l] [Nnf] [OW] | J5: NH3 | K5: CONCTTE | M5: mg/l | N5: Nnf | O5: OW | P5: ChemischeStof | R5: - | T5: NEN 6644:1983 nl | U5: 0.001 | V5: 7664-41-7 | W5: =IFERROR(VLOOKUP($H5,'WNS Dawaco'!$A:$C,2,FALSE),"") -> 25 | X5: =IFERROR(VLOOKUP($H5,'WNS Dawaco'!$A:$C,3,FALSE),"") -> Ammoniak
A6: Fysisch Chemisch onderzoek | B6: OW | C6: 2BEZINK01|OW_BEZ | D6: OW Bezinksel (Imhoff) | E6: Bezinksel (Imhoff) | F6: 2 | G6: Bezinksel | H6: WNS564 | I6: [] [VOLMFTE] [BEZ] [ml/l] [NVT] [OW] | J6: BEZ | K6: VOLMFTE | M6: ml/l | N6: NVT | O6: OW | P6: Object | Q6: VOL | R6: - | T6: NEN 6623:2005 nl | U6: 0.1 | V6: NVT | W6: =IFERROR(VLOOKUP($H6,'WNS Dawaco'!$A:$C,2,FALSE),"") | X6: =IFERROR(VLOOKUP($H6,'WNS Dawaco'!$A:$C,3,FALSE),"")
A7: Fysisch Chemisch onderzoek | B7: OW | C7: 2BLAUW01|OW_FLUOROPROBE | D7: OW Blauwalgen fluoroprobemeting | E7: Blauwalgen fluoroprobemeting | F7: 21 | G7: chlorofyl-a | H7: WNS9321 | I7: [] [CONCTTE] [CHLFa] [ug/l] [diatomee] [OW] | J7: CHLFa | K7: CONCTTE | M7: ug/l | N7: diatomee | O7: OW | P7: ChemischeStof | Q7: FL | R7: - | T7: Eigen methode | U7: 2 | V7: 479-61-8 | W7: =IFERROR(VLOOKUP($H7,'WNS Dawaco'!$A:$C,2,FALSE),"") -> 418 | X7: =IFERROR(VLOOKUP($H7,'WNS Dawaco'!$A:$C,3,FALSE),"") -> Chlorofyl-a diatomee [fluoroprobe]
A8: Fysisch Chemisch onderzoek | B8: OW | C8: 2BLAUW01|OW_FLUOROPROBE | D8: OW Blauwalgen fluoroprobemeting | E8: Blauwalgen fluoroprobemeting | F8: 21 | G8: som 4 chlorofyl-a fracties | H8: WNS10409 | I8: [] [CONCTTE] [sCHLFa4] [ug/l] [NVT] [OW] | J8: sCHLFa4 | K8: CONCTTE | M8: ug/l | N8: NVT | O8: OW | P8: ChemischeStof | Q8: FL | R8: - | T8: Eigen methode | U8: 7 | V8: NVT | W8: =IFERROR(VLOOKUP($H8,'WNS Dawaco'!$A:$C,2,FALSE),"") -> 419 | X8: =IFERROR(VLOOKUP($H8,'WNS Dawaco'!$A:$C,3,FALSE),"") -> Chlorofyl-a [fluoroprobe]
A9: Fysisch Chemisch onderzoek | B9: OW | C9: 2BLAUW01|OW_FLUOROPROBE | D9: OW Blauwalgen fluoroprobemeting | E9: Blauwalgen fluoroprobemeting | F9: 21 | G9: chlorofyl-a | H9: WNS9322 | I9: [] [CONCTTE] [CHLFa] [ug/l] [cryptofy] [OW] | J9: CHLFa | K9: CONCTTE | M9: ug/l | N9: cryptofy | O9: OW | P9: ChemischeStof | Q9: FL | R9: - | T9: Eigen methode | U9: 2 | V9: 479-61-8 | W9: =IFERROR(VLOOKUP($H9,'WNS Dawaco'!$A:$C,2,FALSE),"") -> 417 | X9: =IFERROR(VLOOKUP($H9,'WNS Dawaco'!$A:$C,3,FALSE),"") -> Chlorofyl-a cryptofyten [fluoroprobe]
A10: Fysisch Chemisch onderzoek | B10: OW | C10: 2BLAUW01|OW_FLUOROPROBE | D10: OW Blauwalgen fluoroprobemeting | E10: Blauwalgen fluoroprobemeting | F10: 21 | G10: chlorofyl-a | H10: WNS9320 | I10: [] [CONCTTE] [CHLFa] [ug/l] [groenalg] [OW] | J10: CHLFa | K10: CONCTTE | M10: ug/l | N10: groenalg | O10: OW | P10: ChemischeStof | Q10: FL | R10: - | T10: Eigen methode | U10: 1 | V10: 479-61-8 | W10: =IFERROR(VLOOKUP($H10,'WNS Dawaco'!$A:$C,2,FALSE),"") -> 416 | X10: =IFERROR(VLOOKUP($H10,'WNS Dawaco'!$A:$C,3,FALSE),"") -> Chlorofyl-a groenalg [fluoroprobe]
A11: Fysisch Chemisch onderzoek | B11: OW | C11: 2BLAUW01|OW_FLUOROPROBE | D11: OW Blauwalgen fluoroprobemeting | E11: Blauwalgen fluoroprobemeting | F11: 21 | G11: chlorofyl-a | H11: WNS9253 | I11: [] [CONCTTE] [CHLFa] [ug/l] [blauwalg] [OW] | J11: CHLFa | K11: CONCTTE | M11: ug/l | N11: blauwalg | O11: OW | P11: ChemischeStof | Q11: FL | R11: - | T11: Eigen methode | U11: 2 | V11: 479-61-8 | W11: =IFERROR(VLOOKUP($H11,'WNS Dawaco'!$A:$C,2,FALSE),"") -> 415 | X11: =IFERROR(VLOOKUP($H11,'WNS Dawaco'!$A:$C,3,FALSE),"") -> Chlorofyl-a blauwalg [fluoroprobe]
A12: Fysisch Chemisch onderzoek | B12: OW | C12: 2BLAUW01|OW_FLUOROPROBE | D12: OW Blauwalgen fluoroprobemeting | E12: Blauwalgen fluoroprobemeting | F12: 21 | G12: Fluorescentie | H12: WNS13204 | I12: [] [FLUORCTE] [] [DIMSLS] [EL370nm] [OW] | K12: FLUORCTE | M12: DIMSLS | N12: EL370nm | O12: OW | P12: Grootheid | Q12: FL | R12: - | T12: Eigen methode | U12: 1 | V12: NVT | W12: =IFERROR(VLOOKUP($H12,'WNS Dawaco'!$A:$C,2,FALSE),"") -> 420 | X12: =IFERROR(VLOOKUP($H12,'WNS Dawaco'!$A:$C,3,FALSE),"") -> Humuszuren [fluoroprobe]
A13: Fysisch Chemisch onderzoek | B13: OW | C13: 2BLAUWFY01|OW_FLUOROPROBE | D13: OW Fytoplankton fluoroprobemeting | E13: Fytoplankton fluoroprobemeting | F13: 21 | G13: chlorofyl-a | H13: WNS9253 | I13: [] [CONCTTE] [CHLFa] [ug/l] [blauwalg] [OW] | J13: CHLFa | K13: CONCTTE | M13: ug/l | N13: blauwalg | O13: OW | P13: ChemischeStof | Q13: FL | R13: - | T13: Eigen methode | U13: 2 | V13: 479-61-8 | W13: =IFERROR(VLOOKUP($H13,'WNS Dawaco'!$A:$C,2,FALSE),"") -> 415 | X13: =IFERROR(VLOOKUP($H13,'WNS Dawaco'!$A:$C,3,FALSE),"") -> Chlorofyl-a blauwalg [fluoroprobe]
A14: Fysisch Chemisch onderzoek | B14: OW | C14: 2BLAUWFY01|OW_FLUOROPROBE | D14: OW Fytoplankton fluoroprobemeting | E14: Fytoplankton fluoroprobemeting | F14: 21 | G14: chlorofyl-a | H14: WNS9320 | I14: [] [CONCTTE] [CHLFa] [ug/l] [groenalg] [OW] | J14: CHLFa | K14: CONCTTE | M14: ug/l | N14: groenalg | O14: OW | P14: ChemischeStof | Q14: FL | R14: - | T14: Eigen methode | U14: 1 | V14: 479-61-8 | W14: =IFERROR(VLOOKUP($H14,'WNS Dawaco'!$A:$C,2,FALSE),"") -> 416 | X14: =IFERROR(VLOOKUP($H14,'WNS Dawaco'!$A:$C,3,FALSE),"") -> Chlorofyl-a groenalg [fluoroprobe]
A15: Fysisch Chemisch onderzoek | B15: OW | C15: 2BLAUWFY01|OW_FLUOROPROBE | D15: OW Fytoplankton fluoroprobemeting | E15: Fytoplankton fluoroprobemeting | F15: 21 | G15: chlorofyl-a | H15: WNS9321 | I15: [] [CONCTTE] [CHLFa] [ug/l] [diatomee] [OW] | J15: CHLFa | K15: CONCTTE | M15: ug/l | N15: diatomee | O15: OW | P15: ChemischeStof | Q15: FL | R15: - | T15: Eigen methode | U15: 2 | V15: 479-61-8 | W15: =IFERROR(VLOOKUP($H15,'WNS Dawaco'!$A:$C,2,FALSE),"") -> 418 | X15: =IFERROR(VLOOKUP($H15,'WNS Dawaco'!$A:$C,3,FALSE),"") -> Chlorofyl-a diatomee [fluoroprobe]
A16: Fysisch Chemisch onderzoek | B16: OW | C16: 2BLAUWFY01|OW_FLUOROPROBE | D16: OW Fytoplankton fluoroprobemeting | E16: Fytoplankton fluoroprobemeting | F16: 21 | G16: chlorofyl-a | H16: WNS9322 | I16: [] [CONCTTE] [CHLFa] [ug/l] [cryptofy] [OW] | J16: CHLFa | K16: CONCTTE | M16: ug/l | N16: cryptofy | O16: OW | P16: ChemischeStof | Q16: FL | R16: - | T16: Eigen methode | U16: 2 | V16: 479-61-8 | W16: =IFERROR(VLOOKUP($H16,'WNS Dawaco'!$A:$C,2,FALSE),"") -> 417 | X16: =IFERROR(VLOOKUP($H16,'WNS Dawaco'!$A:$C,3,FALSE),"") -> Chlorofyl-a cryptofyten [fluoroprobe]
A17: Fysisch Chemisch onderzoek | B17: OW | C17: 2BLAUWFY01|OW_FLUOROPROBE | D17: OW Fytoplankton fluoroprobemeting | E17: Fytoplankton fluoroprobemeting | F17: 21 | G17: Fluorescentie | H17: WNS13204 | I17: [] [FLUORCTE] [] [DIMSLS] [EL370nm] [OW] | K17: FLUORCTE | M17: DIMSLS | N17: EL370nm | O17: OW | P17: Grootheid | Q17: FL | R17: - | T17: Eigen methode | U17: 1 | V17: NVT | W17: =IFERROR(VLOOKUP($H17,'WNS Dawaco'!$A:$C,2,FALSE),"") -> 420 | X17: =IFERROR(VLOOKUP($H17,'WNS Dawaco'!$A:$C,3,FALSE),"") -> Humuszuren [fluoroprobe]
A18: Fysisch Chemisch onderzoek | B18: OW | C18: 2BLAUWFY01|OW_FLUOROPROBE | D18: OW Fytoplankton fluoroprobemeting | E18: Fytoplankton fluoroprobemeting | F18: 21 | G18: som 4 chlorofyl-a fracties | H18: WNS10409 | I18: [] [CONCTTE] [sCHLFa4] [ug/l] [NVT] [OW] | J18: sCHLFa4 | K18: CONCTTE | M18: ug/l | N18: NVT | O18: OW | P18: ChemischeStof | Q18: FL | R18: - | T18: Eigen methode | U18: 7 | V18: NVT | W18: =IFERROR(VLOOKUP($H18,'WNS Dawaco'!$A:$C,2,FALSE),"") -> 419 | X18: =IFERROR(VLOOKUP($H18,'WNS Dawaco'!$A:$C,3,FALSE),"") -> Chlorofyl-a [fluoroprobe]
A19: Fysisch Chemisch onderzoek | B19: OW | C19: 2BLAUWPR01|OW_FLUOROPROBE | D19: OW Algemeen fluoroprobemeting | E19: Algemeen fluoroprobemeting | F19: 21 | G19: chlorofyl-a | H19: WNS9320 | I19: [] [CONCTTE] [CHLFa] [ug/l] [groenalg] [OW] | J19: CHLFa | K19: CONCTTE | M19: ug/l | N19: groenalg | O19: OW | P19: ChemischeStof | Q19: FL | R19: - | T19: Eigen methode | U19: 1 | V19: 479-61-8 | W19: =IFERROR(VLOOKUP($H19,'WNS Dawaco'!$A:$C,2,FALSE),"") -> 416 | X19: =IFERROR(VLOOKUP($H19,'WNS Dawaco'!$A:$C,3,FALSE),"") -> Chlorofyl-a groenalg [fluoroprobe]
A20: Fysisch Chemisch onderzoek | B20: OW | C20: 2BLAUWPR01|OW_FLUOROPROBE | D20: OW Algemeen fluoroprobemeting | E20: Algemeen fluoroprobemeting | F20: 21 | G20: som 4 chlorofyl-a fracties | H20: WNS10409 | I20: [] [CONCTTE] [sCHLFa4] [ug/l] [NVT] [OW] | J20: sCHLFa4 | K20: CONCTTE | M20: ug/l | N20: NVT | O20: OW | P20: ChemischeStof | Q20: FL | R20: - | T20: Eigen methode | U20: 7 | V20: NVT | W20: =IFERROR(VLOOKUP($H20,'WNS Dawaco'!$A:$C,2,FALSE),"") -> 419 | X20: =IFERROR(VLOOKUP($H20,'WNS Dawaco'!$A:$C,3,FALSE),"") -> Chlorofyl-a [fluoroprobe]
A21: Fysisch Chemisch onderzoek | B21: OW | C21: 2BLAUWPR01|OW_FLUOROPROBE | D21: OW Algemeen fluoroprobemeting | E21: Algemeen fluoroprobemeting | F21: 21 | G21: Fluorescentie | H21: WNS13204 | I21: [] [FLUORCTE] [] [DIMSLS] [EL370nm] [OW] | K21: FLUORCTE | M21: DIMSLS | N21: EL370nm | O21: OW | P21: Grootheid | Q21: FL | R21: - | T21: Eigen methode | U21: 1 | V21: NVT | W21: =IFERROR(VLOOKUP($H21,'WNS Dawaco'!$A:$C,2,FALSE),"") -> 420 | X21: =IFERROR(VLOOKUP($H21,'WNS Dawaco'!$A:$C,3,FALSE),"") -> Humuszuren [fluoroprobe]
A22: Fysisch Chemisch onderzoek | B22: OW | C22: 2BLAUWPR01|OW_FLUOROPROBE | D22: OW Algemeen fluoroprobemeting | E22: Algemeen fluoroprobemeting | F22: 21 | G22: chlorofyl-a | H22: WNS9322 | I22: [] [CONCTTE] [CHLFa] [ug/l] [cryptofy] [OW] | J22: CHLFa | K22: CONCTTE | M22: ug/l | N22: cryptofy | O22: OW | P22: ChemischeStof | Q22: FL | R22: - | T22: Eigen methode | U22: 2 | V22: 479-61-8 | W22: =IFERROR(VLOOKUP($H22,'WNS Dawaco'!$A:$C,2,FALSE),"") -> 417 | X22: =IFERROR(VLOOKUP($H22,'WNS Dawaco'!$A:$C,3,FALSE),"") -> Chlorofyl-a cryptofyten [fluoroprobe]
A23: Fysisch Chemisch onderzoek | B23: OW | C23: 2BLAUWPR01|OW_FLUOROPROBE | D23: OW Algemeen fluoroprobemeting | E23: Algemeen fluoroprobemeting | F23: 21 | G23: chlorofyl-a | H23: WNS9253 | I23: [] [CONCTTE] [CHLFa] [ug/l] [blauwalg] [OW] | J23: CHLFa | K23: CONCTTE | M23: ug/l | N23: blauwalg | O23: OW | P23: ChemischeStof | Q23: FL | R23: - | T23: Eigen methode | U23: 2 | V23: 479-61-8 | W23: =IFERROR(VLOOKUP($H23,'WNS Dawaco'!$A:$C,2,FALSE),"") -> 415 | X23: =IFERROR(VLOOKUP($H23,'WNS Dawaco'!$A:$C,3,FALSE),"") -> Chlorofyl-a blauwalg [fluoroprobe]
A24: Fysisch Chemisch onderzoek | B24: OW | C24: 2BLAUWPR01|OW_FLUOROPROBE | D24: OW Algemeen fluoroprobemeting | E24: Algemeen fluoroprobemeting | F24: 21 | G24: chlorofyl-a | H24: WNS9321 | I24: [] [CONCTTE] [CHLFa] [ug/l] [diatomee] [OW] | J24: CHLFa | K24: CONCTTE | M24: ug/l | N24: diatomee | O24: OW | P24: ChemischeStof | Q24: FL | R24: - | T24: Eigen methode | U24: 2 | V24: 479-61-8 | W24: =IFERROR(VLOOKUP($H24,'WNS Dawaco'!$A:$C,2,FALSE),"") -> 418 | X24: =IFERROR(VLOOKUP($H24,'WNS Dawaco'!$A:$C,3,FALSE),"") -> Chlorofyl-a diatomee [fluoroprobe]
A25: Fysisch Chemisch onderzoek | B25: OW | C25: 2BZV01|OW_BZV5A | D25: OW Biochemisch zuurstofverbruik, BZV na 5 dagen | E25: Biochemisch zuurstofverbruik, BZV na 5 dagen (verdunde methode) | F25: 14 | G25: Biochemisch zuurstofverbruik met allylthioureum | H25: WNS2864 | I25: [] [CONCTTE] [BZV5a] [mg/l] [O2] [OW] | J25: BZV5a | K25: CONCTTE | M25: mg/l | N25: O2 | O25: OW | P25: ChemischeStof | Q25: LDO | R25: Q | S25: GELIJK | T25: NEN-EN-ISO 5815-1:2019 en | U25: 1 | V25: NVT | W25: =IFERROR(VLOOKUP($H25,'WNS Dawaco'!$A:$C,2,FALSE),"") -> 19 | X25: =IFERROR(VLOOKUP($H25,'WNS Dawaco'!$A:$C,3,FALSE),"") -> Biochemisch zuurstofverbruik in 5 dagen met allylthioureum
A26: Fysisch Chemisch onderzoek | B26: OW | C26: 2CARB01|OW_CO3 | D26: OW Waterstofcarbonaat | E26: Carbonaat | F26: 5 | G26: Carbonaat | H26: WNS6311 | I26: [] [CONCTTE] [CO3] [mg/l] [NVT] [OW] | J26: CO3 | K26: CONCTTE | M26: mg/l | N26: NVT | O26: OW | P26: ChemischeStof | Q26: TITM | R26: - | T26: Eigen methode | U26: 4 | V26: 3812-32-6 | W26: =IFERROR(VLOOKUP($H26,'WNS Dawaco'!$A:$C,2,FALSE),"") -> 31 | X26: =IFERROR(VLOOKUP($H26,'WNS Dawaco'!$A:$C,3,FALSE),"") -> Carbonaat
A27: Fysisch Chemisch onderzoek | B27: OW | C27: 2CARB01|OW_HCO3 | D27: OW Waterstofcarbonaat | E27: Waterstofcarbonaat | F27: 5 | G27: waterstofcarbonaat | H27: WNS2305 | I27: [] [CONCTTE] [HCO3] [mg/l] [NVT] [OW] | J27: HCO3 | K27: CONCTTE | M27: mg/l | N27: NVT | O27: OW | P27: ChemischeStof | Q27: TITM | R27: - | T27: Eigen methode | U27: 4 | V27: 71-52-3 | W27: =IFERROR(VLOOKUP($H27,'WNS Dawaco'!$A:$C,2,FALSE),"") -> 24 | X27: =IFERROR(VLOOKUP($H27,'WNS Dawaco'!$A:$C,3,FALSE),"") -> Waterstofcarbonaat
A28: Fysisch Chemisch onderzoek | B28: OW | C28: 2CHLOROF01|OW_CHLFA | D28: OW Chlorofyl, Faeofytine | E28: Chlorofyl | F28: 21 | G28: Chlorofyl-a | H28: WNS2260 | I28: [] [CONCTTE] [CHLFa] [ug/l] [NVT] [OW] | J28: CHLFa | K28: CONCTTE | M28: ug/l | N28: NVT | O28: OW | P28: ChemischeStof | Q28: UV/VIS | R28: Q | S28: GELIJK | T28: NEN 6520:2006+C1:2011 nl | U28: 3 | V28: 479-61-8 | W28: =IFERROR(VLOOKUP($H28,'WNS Dawaco'!$A:$C,2,FALSE),"") -> 15 | X28: =IFERROR(VLOOKUP($H28,'WNS Dawaco'!$A:$C,3,FALSE),"") -> Chlorofyl-a
A29: Fysisch Chemisch onderzoek | B29: OW | C29: 2CHLOROF01|OW_FEOA | D29: OW Chlorofyl, Faeofytine | E29: Faeofytine | F29: 4 | G29: Feofytine a | H29: WNS2702 | I29: [] [CONCTTE] [FEOa] [ug/l] [NVT] [OW] | J29: FEOa | K29: CONCTTE | M29: ug/l | N29: NVT | O29: OW | P29: ChemischeStof | Q29: UV/VIS | R29: Q | S29: GELIJK | T29: NEN 6520:2006+C1:2011 nl | U29: 5 | V29: NVT | W29: =IFERROR(VLOOKUP($H29,'WNS Dawaco'!$A:$C,2,FALSE),"") -> 16 | X29: =IFERROR(VLOOKUP($H29,'WNS Dawaco'!$A:$C,3,FALSE),"") -> Feofytine a
A30: Fysisch Chemisch onderzoek | B30: OW | C30: 2CRVICUV01|OW_CrVI | D30: OW Chroom VI Cuvettentest | E30: Chroom VI Cuvettentest | F30: 21 | G30: chroom (zeswaardig) | H30: WNS10044 | I30: [] [CONCTTE] [CrVI] [mg/l] [NVT] [OW] | J30: CrVI | K30: CONCTTE | M30: mg/l | N30: NVT | O30: OW | P30: ChemischeStof | Q30: CUVT | R30: - | T30: Eigen methode | U30: 0.03 | V30: 18540-29-9 | W30: =IFERROR(VLOOKUP($H30,'WNS Dawaco'!$A:$C,2,FALSE),"") | X30: =IFERROR(VLOOKUP($H30,'WNS Dawaco'!$A:$C,3,FALSE),"")
A31: Fysisch Chemisch onderzoek | B31: OW | C31: 2EGV01|OW_GELDHD | D31: OW Geleidbaarheid (EGV, gecorrigeerd naar 25 °C door EGV-meter) | E31: Geleidbaarheid (EGV, gecorrigeerd naar 25 °C door EGV-meter), Laboratorium | F31: 3 | G31: Geleidendheid | H31: WNS7128 | I31: [] [GELDHD] [] [uS/cm] [25oC] [OW] | K31: GELDHD | M31: uS/cm | N31: 25oC | O31: OW | P31: Grootheid | Q31: COND | R31: Q | S31: CONFORM | T31: NEN-ISO 7888:1994 en | U31: 10 | W31: =IFERROR(VLOOKUP($H31,'WNS Dawaco'!$A:$C,2,FALSE),"") -> 9 | X31: =IFERROR(VLOOKUP($H31,'WNS Dawaco'!$A:$C,3,FALSE),"") -> Geleidendheid bij 25oC
A32: Fysisch Chemisch onderzoek | B32: OW | C32: 2EGV01|OW_GELDHD | D32: OW Geleidbaarheid (EGV, gecorrigeerd naar 25 °C door EGV-meter) | E32: Geleidbaarheid (EGV, gecorrigeerd naar 25 °C door EGV-meter), Laboratorium | F32: 3 | G32: Temperatuur | K32: T | M32: oC | N32: NVT | O32: OW | P32: Grootheid | Q32: COND | R32: - | U32: 0 | W32: =IFERROR(VLOOKUP($H32,'WNS Dawaco'!$A:$C,2,FALSE),"") | X32: =IFERROR(VLOOKUP($H32,'WNS Dawaco'!$A:$C,3,FALSE),"")
A33: Fysisch Chemisch onderzoek | B33: OW | C33: 2EXT25401|OW_EXT254 | D33: OW Extinctie 254nm | E33: Extinctie 254nm | F33: 15 | G33: Extinctie | H33: WNS9998 | I33: [] [E] [] [DIMSLS] [L254nm] [OW] | K33: E | M33: DIMSLS | N33: L254nm | O33: OW | P33: Grootheid | Q33: UV/VIS | R33: - | T33: Eigen methode | U33: 0 | W33: =IFERROR(VLOOKUP($H33,'WNS Dawaco'!$A:$C,2,FALSE),"") | X33: =IFERROR(VLOOKUP($H33,'WNS Dawaco'!$A:$C,3,FALSE),"")
A34: Fysisch Chemisch onderzoek | B34: OW | C34: 2EXT38001|OW_EXT380 | D34: OW Extinctie 380nm | E34: Extinctie 380nm | F34: 6 | G34: Extinctie | H34: WNS999 | I34: [] [E] [] [DIMSLS] [L380nm] [OW] | K34: E | M34: DIMSLS | N34: L380nm | O34: OW | P34: Grootheid | Q34: UV/VIS | R34: - | T34: Eigen methode | U34: 0.01 | W34: =IFERROR(VLOOKUP($H34,'WNS Dawaco'!$A:$C,2,FALSE),"") | X34: =IFERROR(VLOOKUP($H34,'WNS Dawaco'!$A:$C,3,FALSE),"")
A35: Fysisch Chemisch onderzoek | B35: OW | C35: 2FEIICUV01|OW_FeII | D35: OW Ijzer II Cuvettentest | E35: Ijzer II Cuvettentest | F35: 21 | G35: ijzer (tweewaardig) | H35: WNS1048 | I35: [] [CONCTTE] [FeII] [mg/l] [NVT] [OW] | J35: FeII | K35: CONCTTE | M35: mg/l | N35: NVT | O35: OW | P35: ChemischeStof | Q35: CUVT | R35: - | T35: Eigen methode | U35: 0.2 | V35: 15438-31-0 | W35: =IFERROR(VLOOKUP($H35,'WNS Dawaco'!$A:$C,2,FALSE),"") -> 222 | X35: =IFERROR(VLOOKUP($H35,'WNS Dawaco'!$A:$C,3,FALSE),"") -> ijzer (tweewaardig)
A36: Fysisch Chemisch onderzoek | B36: OW | C36: 2FILLAB01|OW_FILLAB | D36: OW Filtratie AQ054 op lab | E36: Filtratie AQ054 op lab | F36: 15 | R36: - | U36: 0 | W36: =IFERROR(VLOOKUP($H36,'WNS Dawaco'!$A:$C,2,FALSE),"") | X36: =IFERROR(VLOOKUP($H36,'WNS Dawaco'!$A:$C,3,FALSE),"")
A37: Fysisch Chemisch onderzoek | B37: OW | C37: 2FILLB3101|OW_FILLB31 | D37: OW Filtratie AQ031 op lab | E37: Filtratie AQ031 op lab | F37: 15 | R37: - | U37: 0 | W37: =IFERROR(VLOOKUP($H37,'WNS Dawaco'!$A:$C,2,FALSE),"") | X37: =IFERROR(VLOOKUP($H37,'WNS Dawaco'!$A:$C,3,FALSE),"")
A38: Overig | B38: OW | C38: 2FLS1701|OW_FLS1701 | D38: OW Extra fles AQ017 | E38: Extra fles AQ017 | F38: 0 | M38: DIMSLS | R38: - | U38: 0 | W38: =IFERROR(VLOOKUP($H38,'WNS Dawaco'!$A:$C,2,FALSE),"") | X38: =IFERROR(VLOOKUP($H38,'WNS Dawaco'!$A:$C,3,FALSE),"")
A39: Overig | B39: OW | C39: 2FLS2001|OW_FLS2001 | D39: OW Extra fles AQ020 | E39: Exttra fles AQ020 | F39: 0 | M39: DIMSLS | R39: - | U39: 0 | W39: =IFERROR(VLOOKUP($H39,'WNS Dawaco'!$A:$C,2,FALSE),"") | X39: =IFERROR(VLOOKUP($H39,'WNS Dawaco'!$A:$C,3,FALSE),"")
A40: Overig | B40: OW | C40: 2FLS2301|OW_FLS23 | D40: OW Extra fles AQ023 | E40: Extra fles AQ023 | F40: 0 | M40: DIMSLS | R40: - | U40: 0 | W40: =IFERROR(VLOOKUP($H40,'WNS Dawaco'!$A:$C,2,FALSE),"") | X40: =IFERROR(VLOOKUP($H40,'WNS Dawaco'!$A:$C,3,FALSE),"")
...

Sheet frequentiecodes
A1: frequentie_code | B1: frequentie_omschrijving | C1: aantal_metingen | D1: toelichting
A2: 1_apr | B2: eenmalig in april | C2: 1 | D2: =""
A3: 1_jul | B3: eenmalig in juli | C3: 1 | D3: =""
A4: 1_mafa | B4: eenmalig in mei of juni | C4: 1 | D4: =""
A5: 1_mafy | B5: eenmalig tussen 15 juni en 15 augusutus | C5: 1 | D5: =""
A6: 1_mei | B6: eenmalig in mei | C6: 1 | D6: =""
A7: 1_vis | B7: eenmalig tussen 15 juli en 30 september | C7: 1 | D7: =""
A8: 11_2w_jun_okt | B8: Tweewekelijks van juni tot en met oktober | C8: 11 | D8: =""
A9: 12_m | B9: maandelijks | C9: 12 | D9: =""
A10: 12_zwem | B10: tweewekelijks in het zwemseizoen | C10: 12 | D10: op weeknummer
A11: 3_mjj | B11: Mei, juni en juli | C11: 3 | D11: =""
A12: 3_zwem | B12: begin, midden en eind zwemseizoen | C12: 3 | D12: op weeknummer
A13: 4_gbm | B13: in de maanden januari, april, juli en september | C13: 4 | D13: januari, april, juli, september - gbm
A14: 4_krw | B14: In de maanden februari, mei, augustus en november | C14: 4 | D14: =""
A15: 4_mjja | B15: Mei, juni, juli en augustus | C15: 4 | D15: =""
A16: 4_zomer | B16: 4 keer in het zomerhalfjaar | C16: 4 | D16: =""
A17: 6_m_oneven | B17: in de oneven maanden | C17: 6 | D17: januari, maart, mei, juli, september, november
A18: 7_2w_apr_jun | B18: Tweewekelijks april tot en met juni | C18: 7 | D18: =""
A19: 7_m | B19: maandelijks van maart tot september | C19: 7 | D19: =""
A20: afwijkend | B20: afwijkende frequentie | C20: ="" | D20: =""
A21: 4_kwartaal_1 | B21: Elk kwartaal in eerste maand (januari, april, juli en oktober) | C21: 4 | D21: =""
A22: 1_kreeft | B22: Eenmalig in mei of juni | C22: 1 | D22: =""
A23: 4_amjj | B23: April, mei, juni en juli | C23: 4 | D23: =""
A24: 5_mjjas | B24: Mei, juni, juli, augustus, september | C24: 5 | D24: =""
A25: 12_m_zwem | B25: maandelijks icm zwemwater | C25: 12 | D25: maandelijks metingen, in de zomer op weeknummer
A26: 1_mei_zwem | B26: Eenmalig in mei, week 19 | C26: 1 | D26: Meting in mei - op weeknummer
A27: 6_m_zomer | B27: maandelijks van april tot en met september | C27: 6 | D27: =""
A28: 10_1w_42_51 | B28: Wekelijks van week 42 tot en met week 51 (10x) | C28: 10 | D28: ivm toepassing Phoslock
A29: 3_4w_42_50 | B29: Vierwekelijks van week 42 tot en met week 50 | C29: 3 | D29: ivm toepassing Phoslock
A30: 1_jan | B30: eenmalig in januari | C30: 1 | D30: =""
A31: 1_w23 | B31: eenmalig in week 23 | C31: 1 | D31: =""
A32: 1_mrt | B32: eenmalig in maart | C32: 1 | D32: =""
A33: 2_feb_aug | B33: februari en augustus | C33: 2 | D33: =""
A34: 2_jan_jul | B34: januari en juli | C34: 2 | D34: =""
A35: 1_feb | B35: eenmalig in februari | C35: 1 | D35: =""
A36: 8_m_mei_dec | B36: maandelijks van mei t/m december | C36: 8 | D36: =""
A37: 1_aug | B37: eenmalig in augustus | C37: 1 | D37: =""
A38: 11_2w_mei_sept | B38: Tweewekelijks van mei tot en met september | C38: 11 | D38: =""
A39: 1_w_19 | B39: eenmalig in week 19 | C39: 1 | D39: =""
A40: 10_zwem | B40: Tweewekelijks in het zwemseizoen t/m augustus | C40: 10 | D40: =""
...

Sheet frequenties
